Workbook
Name UPDATE: 'Data Sheet'!$E$1

Sheet Quarters
A1: ='Profit & Loss'!A1 -> ITC LTD | E1: =UPDATE -> ITC LTD | J1: SCREENER.IN
A3: Narration | B3: ='Data Sheet'!B41 -> 45199 | C3: ='Data Sheet'!C41 -> 45291 | D3: ='Data Sheet'!D41 -> 45382 | E3: ='Data Sheet'!E41 -> 45473 | F3: ='Data Sheet'!F41 -> 45565 | G3: ='Data Sheet'!G41 -> 45657 | H3: ='Data Sheet'!H41 -> 45747 | I3: ='Data Sheet'!I41 -> 45838 | ... K3: ='Data Sheet'!K41 -> 46022
A4: Sales | B4: ='Data Sheet'!B42 -> 17774.47 | C4: ='Data Sheet'!C42 -> 17195.24 | D4: ='Data Sheet'!D42 -> 17037.8 | E4: ='Data Sheet'!E42 -> 17777.81 | F4: ='Data Sheet'!F42 -> 19990.36 | G4: ='Data Sheet'!G42 -> 18790.17 | H4: ='Data Sheet'!H42 -> 18765 | I4: ='Data Sheet'!I42 -> 21494.79 | ... K4: ='Data Sheet'!K42 -> 20047.3
A5: Expenses | B5: ='Data Sheet'!B43 -> 11320.23 | C5: ='Data Sheet'!C43 -> 10985.01 | D5: ='Data Sheet'!D43 -> 10735.73 | E5: ='Data Sheet'!E43 -> 11232.97 | F5: ='Data Sheet'!F43 -> 13438.28 | G5: ='Data Sheet'!G43 -> 12428.27 | H5: ='Data Sheet'!H43 -> 12245.61 | I5: ='Data Sheet'!I43 -> 14678.32 | ... K5: ='Data Sheet'!K43 -> 13164.78
A6: Operating Profit | B6: ='Data Sheet'!B50 -> 6454.24 | C6: ='Data Sheet'!C50 -> 6210.23 | D6: ='Data Sheet'!D50 -> 6302.07 | E6: ='Data Sheet'!E50 -> 6544.84 | F6: ='Data Sheet'!F50 -> 6552.08 | G6: ='Data Sheet'!G50 -> 6361.9 | H6: ='Data Sheet'!H50 -> 6519.39 | I6: ='Data Sheet'!I50 -> 6816.47 | ... K6: ='Data Sheet'!K50 -> 6882.52
A7: Other Income | B7: ='Data Sheet'!B44 -> 673.5 | C7: ='Data Sheet'!C44 -> 820.26 | D7: ='Data Sheet'!D44 -> 868 | E7: ='Data Sheet'!E44 -> 771.13 | F7: ='Data Sheet'!F44 -> 690.31 | G7: ='Data Sheet'!G44 -> 803.4 | H7: ='Data Sheet'!H44 -> 15391.28 | I7: ='Data Sheet'!I44 -> 750.97 | ... K7: ='Data Sheet'!K44 -> 321.85
A8: Depreciation | B8: ='Data Sheet'!B45 -> 453.04 | C8: ='Data Sheet'!C45 -> 384.04 | D8: ='Data Sheet'!D45 -> 385.09 | E8: ='Data Sheet'!E45 -> 403.13 | F8: ='Data Sheet'!F45 -> 416.18 | G8: ='Data Sheet'!G45 -> 415.98 | H8: ='Data Sheet'!H45 -> 411.03 | I8: ='Data Sheet'!I45 -> 422.96 | ... K8: ='Data Sheet'!K45 -> 430.82
A9: Interest | B9: ='Data Sheet'!B46 -> 9.87 | C9: ='Data Sheet'!C46 -> 11.94 | D9: ='Data Sheet'!D46 -> 10.72 | E9: ='Data Sheet'!E46 -> 9.6 | F9: ='Data Sheet'!F46 -> 14.73 | G9: ='Data Sheet'!G46 -> 9.82 | H9: ='Data Sheet'!H46 -> 10.91 | I9: ='Data Sheet'!I46 -> 16.47 | ... K9: ='Data Sheet'!K46 -> 19.47
A10: Profit before tax | B10: ='Data Sheet'!B47 -> 6664.83 | C10: ='Data Sheet'!C47 -> 6634.51 | D10: ='Data Sheet'!D47 -> 6774.26 | E10: ='Data Sheet'!E47 -> 6903.24 | F10: ='Data Sheet'!F47 -> 6811.48 | G10: ='Data Sheet'!G47 -> 6739.5 | H10: ='Data Sheet'!H47 -> 21488.73 | I10: ='Data Sheet'!I47 -> 7128.01 | ... K10: ='Data Sheet'!K47 -> 6754.08
A11: Tax | B11: ='Data Sheet'!B48 -> 1700.31 | C11: ='Data Sheet'!C48 -> 1227.99 | D11: ='Data Sheet'!D48 -> 1583.55 | E11: ='Data Sheet'!E48 -> 1726.25 | F11: ='Data Sheet'!F48 -> 1757.05 | G11: ='Data Sheet'!G48 -> 1726.32 | H11: ='Data Sheet'!H48 -> 1680.85 | I11: ='Data Sheet'!I48 -> 1784.6 | ... K11: ='Data Sheet'!K48 -> 1735.63
A12: Net profit | B12: ='Data Sheet'!B49 -> 4898.07 | C12: ='Data Sheet'!C49 -> 5335.23 | D12: ='Data Sheet'!D49 -> 5120.55 | E12: ='Data Sheet'!E49 -> 5091.59 | F12: ='Data Sheet'!F49 -> 4992.87 | G12: ='Data Sheet'!G49 -> 4934.8 | H12: ='Data Sheet'!H49 -> 19727.37 | I12: ='Data Sheet'!I49 -> 5244.2 | ... K12: ='Data Sheet'!K49 -> 4931.19
A14: OPM | B14: =IF(B4>0,B6/B4,"") -> 0.36311856 | C14: =IF(C4>0,C6/C4,"") -> 0.36115983 | D14: =IF(D4>0,D6/D4,"") -> 0.36988754 | E14: =IF(E4>0,E6/E4,"") -> 0.36814658 | F14: =IF(F4>0,F6/F4,"") -> 0.32776198 | G14: =IF(G4>0,G6/G4,"") -> 0.33857597 | H14: =IF(H4>0,H6/H4,"") -> 0.34742286 | I14: =IF(I4>0,I6/I4,"") -> 0.31712196 | ... K14: =IF(K4>0,K6/K4,"") -> 0.34331406

Sheet Balance Sheet
A1: ='Profit & Loss'!A1 -> ITC LTD | E1: =UPDATE -> ITC LTD | J1: SCREENER.IN
A3: Narration | B3: ='Data Sheet'!B56 -> 42460 | C3: ='Data Sheet'!C56 -> 42825 | D3: ='Data Sheet'!D56 -> 43190 | E3: ='Data Sheet'!E56 -> 43555 | F3: ='Data Sheet'!F56 -> 43921 | G3: ='Data Sheet'!G56 -> 44286 | H3: ='Data Sheet'!H56 -> 44651 | I3: ='Data Sheet'!I56 -> 45016 | ... K3: ='Data Sheet'!K56 -> 45747
A4: Equity Share Capital | B4: ='Data Sheet'!B57 -> 804.72 | C4: ='Data Sheet'!C57 -> 1214.74 | D4: ='Data Sheet'!D57 -> 1220.43 | E4: ='Data Sheet'!E57 -> 1225.86 | F4: ='Data Sheet'!F57 -> 1229.22 | G4: ='Data Sheet'!G57 -> 1230.88 | H4: ='Data Sheet'!H57 -> 1232.33 | I4: ='Data Sheet'!I57 -> 1242.8 | ... K4: ='Data Sheet'!K57 -> 1251.41
A5: Reserves | B5: ='Data Sheet'!B58 -> 41874.8 | C5: ='Data Sheet'!C58 -> 45198.19 | D5: ='Data Sheet'!D58 -> 51289.68 | E5: ='Data Sheet'!E58 -> 57915.01 | F5: ='Data Sheet'!F58 -> 64044.04 | G5: ='Data Sheet'!G58 -> 59116.46 | H5: ='Data Sheet'!H58 -> 61223.24 | I5: ='Data Sheet'!I58 -> 67912.46 | ... K5: ='Data Sheet'!K58 -> 68778.64
A6: Borrowings | B6: ='Data Sheet'!B59 -> 83.78 | C6: ='Data Sheet'!C59 -> 45.72 | D6: ='Data Sheet'!D59 -> 35.92 | E6: ='Data Sheet'!E59 -> 13.44 | F6: ='Data Sheet'!F59 -> 277.45 | G6: ='Data Sheet'!G59 -> 270.83 | H6: ='Data Sheet'!H59 -> 249.44 | I6: ='Data Sheet'!I59 -> 306.04 | ... K6: ='Data Sheet'!K59 -> 284.54
A7: Other Liabilities | B7: ='Data Sheet'!B60 -> 8888.04 | C7: ='Data Sheet'!C60 -> 9439.67 | D7: ='Data Sheet'!D60 -> 11694.85 | E7: ='Data Sheet'!E60 -> 12584.73 | F7: ='Data Sheet'!F60 -> 11760.04 | G7: ='Data Sheet'!G60 -> 13142.59 | H7: ='Data Sheet'!H60 -> 14491.01 | I7: ='Data Sheet'!I60 -> 16369.66 | ... K7: ='Data Sheet'!K60 -> 17688.11
A8: Total | B8: ='Data Sheet'!B61 -> 51651.34 | C8: ='Data Sheet'!C61 -> 55898.32 | D8: ='Data Sheet'!D61 -> 64240.88 | E8: ='Data Sheet'!E61 -> 71739.04 | F8: ='Data Sheet'!F61 -> 77310.75 | G8: ='Data Sheet'!G61 -> 73760.76 | H8: ='Data Sheet'!H61 -> 77196.02 | I8: ='Data Sheet'!I61 -> 85830.96 | ... K8: ='Data Sheet'!K61 -> 88002.7
A10: Net Block | B10: ='Data Sheet'!B62 -> 15106.63 | C10: ='Data Sheet'!C62 -> 15893.48 | D10: ='Data Sheet'!D62 -> 16523.96 | E10: ='Data Sheet'!E62 -> 19374.19 | F10: ='Data Sheet'!F62 -> 21713.34 | G10: ='Data Sheet'!G62 -> 23298.48 | H10: ='Data Sheet'!H62 -> 24231.59 | I10: ='Data Sheet'!I62 -> 25851.27 | ... K10: ='Data Sheet'!K62 -> 21954.85
A11: Capital Work in Progress | B11: ='Data Sheet'!B63 -> 2559.72 | C11: ='Data Sheet'!C63 -> 3729.89 | D11: ='Data Sheet'!D63 -> 5508.33 | E11: ='Data Sheet'!E63 -> 4136.42 | F11: ='Data Sheet'!F63 -> 3256.46 | G11: ='Data Sheet'!G63 -> 4011.29 | H11: ='Data Sheet'!H63 -> 3225.54 | I11: ='Data Sheet'!I63 -> 3003.3 | ... K11: ='Data Sheet'!K63 -> 1090.91
A12: Investments | B12: ='Data Sheet'!B64 -> 11747.59 | C12: ='Data Sheet'!C64 -> 17581.38 | D12: ='Data Sheet'!D64 -> 22052.86 | E12: ='Data Sheet'!E64 -> 25043.49 | F12: ='Data Sheet'!F64 -> 28663.35 | G12: ='Data Sheet'!G64 -> 24870.87 | H12: ='Data Sheet'!H64 -> 24841.01 | I12: ='Data Sheet'!I64 -> 29415.02 | ... K12: ='Data Sheet'!K64 -> 34719.82
A13: Other Assets | B13: ='Data Sheet'!B65 -> 22237.4 | C13: ='Data Sheet'!C65 -> 18693.57 | D13: ='Data Sheet'!D65 -> 20155.73 | E13: ='Data Sheet'!E65 -> 23184.94 | F13: ='Data Sheet'!F65 -> 23677.6 | G13: ='Data Sheet'!G65 -> 21580.12 | H13: ='Data Sheet'!H65 -> 24897.88 | I13: ='Data Sheet'!I65 -> 27561.37 | ... K13: ='Data Sheet'!K65 -> 30237.12
A14: Total | B14: ='Data Sheet'!B66 -> 51651.34 | C14: ='Data Sheet'!C66 -> 55898.32 | D14: ='Data Sheet'!D66 -> 64240.88 | E14: ='Data Sheet'!E66 -> 71739.04 | F14: ='Data Sheet'!F66 -> 77310.75 | G14: ='Data Sheet'!G66 -> 73760.76 | H14: ='Data Sheet'!H66 -> 77196.02 | I14: ='Data Sheet'!I66 -> 85830.96 | ... K14: ='Data Sheet'!K66 -> 88002.7
A16: Working Capital | B16: =B13-B7 -> 13349.36 | C16: =C13-C7 -> 9253.9 | D16: =D13-D7 -> 8460.88 | E16: =E13-E7 -> 10600.21 | F16: =F13-F7 -> 11917.56 | G16: =G13-G7 -> 8437.53 | H16: =H13-H7 -> 10406.87 | I16: =I13-I7 -> 11191.71 | ... K16: =K13-K7 -> 12549.01
A17: Debtors | B17: ='Data Sheet'!B67 -> 1917.18 | C17: ='Data Sheet'!C67 -> 2474.29 | D17: ='Data Sheet'!D67 -> 2682.29 | E17: ='Data Sheet'!E67 -> 4035.28 | F17: ='Data Sheet'!F67 -> 2562.48 | G17: ='Data Sheet'!G67 -> 2501.7 | H17: ='Data Sheet'!H67 -> 2461.9 | I17: ='Data Sheet'!I67 -> 2956.17 | ... K17: ='Data Sheet'!K67 -> 4719.67
A18: Inventory | B18: ='Data Sheet'!B68 -> 9062.1 | C18: ='Data Sheet'!C68 -> 8116.1 | D18: ='Data Sheet'!D68 -> 7495.09 | E18: ='Data Sheet'!E68 -> 7859.56 | F18: ='Data Sheet'!F68 -> 8879.33 | G18: ='Data Sheet'!G68 -> 10397.16 | H18: ='Data Sheet'!H68 -> 10864.15 | I18: ='Data Sheet'!I68 -> 11771.16 | ... K18: ='Data Sheet'!K68 -> 15637.56
A20: Debtor Days | B20: =IF('Profit & Loss'!B4>0,'Balance Sheet'!B17/('Profit & Loss'!B4/365),0) -> 17.854892 | C20: =IF('Profit & Loss'!C4>0,'Balance Sheet'!C17/('Profit & Loss'!C4/365),0) -> 21.116823 | D20: =IF('Profit & Loss'!D4>0,'Balance Sheet'!D17/('Profit & Loss'!D4/365),0) -> 22.53302 | E20: =IF('Profit & Loss'!E4>0,'Balance Sheet'!E17/('Profit & Loss'!E4/365),0) -> 30.469383 | F20: =IF('Profit & Loss'!F4>0,'Balance Sheet'!F17/('Profit & Loss'!F4/365),0) -> 18.938019 | G20: =IF('Profit & Loss'!G4>0,'Balance Sheet'!G17/('Profit & Loss'!G4/365),0) -> 18.537714 | H20: =IF('Profit & Loss'!H4>0,'Balance Sheet'!H17/('Profit & Loss'!H4/365),0) -> 14.817385 | I20: =IF('Profit & Loss'!I4>0,'Balance Sheet'!I17/('Profit & Loss'!I4/365),0) -> 15.214563 | ... K20: =IF('Profit & Loss'!K4>0,'Balance Sheet'!K17/('Profit & Loss'!K4/365),0) -> 22.870462
A21: Inventory Turnover | B21: =IF('Balance Sheet'!B18>0,'Profit & Loss'!B4/'Balance Sheet'!B18,0) -> 4.3248364 | C21: =IF('Balance Sheet'!C18>0,'Profit & Loss'!C4/'Balance Sheet'!C18,0) -> 5.2694767 | D21: =IF('Balance Sheet'!D18>0,'Profit & Loss'!D4/'Balance Sheet'!D18,0) -> 5.7969871 | E21: =IF('Balance Sheet'!E18>0,'Profit & Loss'!E4/'Balance Sheet'!E18,0) -> 6.1504181 | F21: =IF('Balance Sheet'!F18>0,'Profit & Loss'!F4/'Balance Sheet'!F18,0) -> 5.5620976 | G21: =IF('Balance Sheet'!G18>0,'Profit & Loss'!G4/'Balance Sheet'!G18,0) -> 4.737587 | H21: =IF('Balance Sheet'!H18>0,'Profit & Loss'!H4/'Balance Sheet'!H18,0) -> 5.5820787 | I21: =IF('Balance Sheet'!I18>0,'Profit & Loss'!I4/'Balance Sheet'!I18,0) -> 6.0248123 | ... K21: =IF('Balance Sheet'!K18>0,'Profit & Loss'!K4/'Balance Sheet'!K18,0) -> 4.8168218
A23: Return on Equity | B23: =IF(SUM('Balance Sheet'!B4:B5)>0,'Profit & Loss'!B12/SUM('Balance Sheet'!B4:B5),"") -> 0.21894459 | C23: =IF(SUM('Balance Sheet'!C4:C5)>0,'Profit & Loss'!C12/SUM('Balance Sheet'!C4:C5),"") -> 0.22169339 | D23: =IF(SUM('Balance Sheet'!D4:D5)>0,'Profit & Loss'!D12/SUM('Balance Sheet'!D4:D5),"") -> 0.21464819 | E23: =IF(SUM('Balance Sheet'!E4:E5)>0,'Profit & Loss'!E12/SUM('Balance Sheet'!E4:E5),"") -> 0.21292095 | F23: =IF(SUM('Balance Sheet'!F4:F5)>0,'Profit & Loss'!F12/SUM('Balance Sheet'!F4:F5),"") -> 0.23449465 | G23: =IF(SUM('Balance Sheet'!G4:G5)>0,'Profit & Loss'!G12/SUM('Balance Sheet'!G4:G5),"") -> 0.21809064 | H23: =IF(SUM('Balance Sheet'!H4:H5)>0,'Profit & Loss'!H12/SUM('Balance Sheet'!H4:H5),"") -> 0.24405605 | I23: =IF(SUM('Balance Sheet'!I4:I5)>0,'Profit & Loss'!I12/SUM('Balance Sheet'!I4:I5),"") -> 0.27751555 | ... K23: =IF(SUM('Balance Sheet'!K4:K5)>0,'Profit & Loss'!K12/SUM('Balance Sheet'!K4:K5),"") -> 0.49616743
A24: Return on Capital Emp | C24: =IF((B4+B5+B6+C4+C5+C6)>0,('Profit & Loss'!C10+'Profit & Loss'!C9)*2/(B4+B5+B6+C4+C5+C6),"") -> 0.36034518 | D24: =IF((C4+C5+C6+D4+D5+D6)>0,('Profit & Loss'!D10+'Profit & Loss'!D9)*2/(C4+C5+C6+D4+D5+D6),"") -> 0.35400589 | E24: =IF((D4+D5+D6+E4+E5+E6)>0,('Profit & Loss'!E10+'Profit & Loss'!E9)*2/(D4+D5+D6+E4+E5+E6),"") -> 0.34415688 | F24: =IF((E4+E5+E6+F4+F5+F6)>0,('Profit & Loss'!F10+'Profit & Loss'!F9)*2/(E4+E5+E6+F4+F5+F6),"") -> 0.32261652 | G24: =IF((F4+F5+F6+G4+G5+G6)>0,('Profit & Loss'!G10+'Profit & Loss'!G9)*2/(F4+F5+F6+G4+G5+G6),"") -> 0.28527066 | H24: =IF((G4+G5+G6+H4+H5+H6)>0,('Profit & Loss'!H10+'Profit & Loss'!H9)*2/(G4+G5+G6+H4+H5+H6),"") -> 0.33733253 | I24: =IF((H4+H5+H6+I4+I5+I6)>0,('Profit & Loss'!I10+'Profit & Loss'!I9)*2/(H4+H5+H6+I4+I5+I6),"") -> 0.39333609 | J24: =IF((I4+I5+I6+J4+J5+J6)>0,('Profit & Loss'!J10+'Profit & Loss'!J9)*2/(I4+I5+I6+J4+J5+J6),"") -> 0.37429273 | K24: =IF((J4+J5+J6+K4+K5+K6)>0,('Profit & Loss'!K10+'Profit & Loss'!K9)*2/(J4+J5+J6+K4+K5+K6),"") -> 0.57864605
A26: Book Value | E26: =E4+E5 -> 59140.87 | F26: =F4+F5 -> 65273.26 | G26: =G4+G5 -> 60347.34 | H26: =H4+H5 -> 62455.57 | I26: =I4+I5 -> 69155.26 | J26: =J4+J5 -> 74507 | K26: =K4+K5 -> 70030.05

Sheet Cash Flow
A1: ='Balance Sheet'!A1 -> ITC LTD | E1: =UPDATE -> ITC LTD | J1: SCREENER.IN
A3: Narration | B3: ='Data Sheet'!B81 -> 42460 | C3: ='Data Sheet'!C81 -> 42825 | D3: ='Data Sheet'!D81 -> 43190 | E3: ='Data Sheet'!E81 -> 43555 | F3: ='Data Sheet'!F81 -> 43921 | G3: ='Data Sheet'!G81 -> 44286 | H3: ='Data Sheet'!H81 -> 44651 | I3: ='Data Sheet'!I81 -> 45016 | ... K3: ='Data Sheet'!K81 -> 45747
A4: Cash from Operating Activity | B4: ='Data Sheet'!B82 -> 9799.04 | C4: ='Data Sheet'!C82 -> 10627.31 | D4: ='Data Sheet'!D82 -> 13169.4 | E4: ='Data Sheet'!E82 -> 12583.41 | F4: ='Data Sheet'!F82 -> 14689.66 | G4: ='Data Sheet'!G82 -> 12526.97 | H4: ='Data Sheet'!H82 -> 15775.51 | I4: ='Data Sheet'!I82 -> 18877.55 | ... K4: ='Data Sheet'!K82 -> 17627.04
A5: Cash from Investing Activity | B5: ='Data Sheet'!B83 -> -3920.73 | C5: ='Data Sheet'!C83 -> -3250.93 | D5: ='Data Sheet'!D83 -> -7113.89 | E5: ='Data Sheet'!E83 -> -5545.68 | F5: ='Data Sheet'!F83 -> -6174.02 | G5: ='Data Sheet'!G83 -> 5739.98 | H5: ='Data Sheet'!H83 -> -2238.49 | I5: ='Data Sheet'!I83 -> -5732.29 | ... K5: ='Data Sheet'!K83 -> -563.84
A6: Cash from Financing Activity | B6: ='Data Sheet'!B84 -> -5612.52 | C6: ='Data Sheet'!C84 -> -7301.03 | D6: ='Data Sheet'!D84 -> -6221.13 | E6: ='Data Sheet'!E84 -> -6868.64 | F6: ='Data Sheet'!F84 -> -8181.48 | G6: ='Data Sheet'!G84 -> -18633.83 | H6: ='Data Sheet'!H84 -> -13580.5 | I6: ='Data Sheet'!I84 -> -13006.03 | ... K6: ='Data Sheet'!K84 -> -17037.4
A7: Net Cash Flow | B7: ='Data Sheet'!B85 -> 265.79 | C7: ='Data Sheet'!C85 -> 75.35 | D7: ='Data Sheet'!D85 -> -165.62 | E7: ='Data Sheet'!E85 -> 169.09 | F7: ='Data Sheet'!F85 -> 334.16 | G7: ='Data Sheet'!G85 -> -366.88 | H7: ='Data Sheet'!H85 -> -43.48 | I7: ='Data Sheet'!I85 -> 139.23 | ... K7: ='Data Sheet'!K85 -> 25.8

Sheet Customization
A1: How to use it?
A3: You can customize this workbook as you want.
B4: You can add custom formating, add conditional formating, add your own formulas… do ANYTHING.
B5: Please don't edit the "Data Sheet" only.
A7: After customization, you can upload this back on Screener.
B8: Upload on: | C8: https://www.screener.in/excel/
A10: Download your customized workbooks now onwards.
B11: Now whenever you will "Export to excel" from Screener, it will export your customized file.
A14: TESTING:
B15: This is a testing feature currently.
B16: You can report any formula errors on the worksheet at: support@screener.in

Sheet Profit & Loss
A1: ='Data Sheet'!B1 -> ITC LTD | H1: =UPDATE -> ITC LTD | M1: SCREENER.IN
A3: Narration | B3: ='Data Sheet'!B16 -> 42460 | C3: ='Data Sheet'!C16 -> 42825 | D3: ='Data Sheet'!D16 -> 43190 | E3: ='Data Sheet'!E16 -> 43555 | F3: ='Data Sheet'!F16 -> 43921 | G3: ='Data Sheet'!G16 -> 44286 | H3: ='Data Sheet'!H16 -> 44651 | I3: ='Data Sheet'!I16 -> 45016 | ... K3: ='Data Sheet'!K16 -> 45747 | L3: Trailing | M3: Best Case | N3: Worst Case
A4: Sales | B4: ='Data Sheet'!B17 -> 39192.1 | C4: ='Data Sheet'!C17 -> 42767.6 | D4: ='Data Sheet'!D17 -> 43448.94 | E4: ='Data Sheet'!E17 -> 48339.58 | F4: ='Data Sheet'!F17 -> 49387.7 | G4: ='Data Sheet'!G17 -> 49257.45 | H4: ='Data Sheet'!H17 -> 60644.54 | I4: ='Data Sheet'!I17 -> 70919.03 | ... K4: ='Data Sheet'!K17 -> 75323.34 | L4: =SUM(Quarters!H4:K4) -> 79808.72 | M4: =$K4+M23*K4 -> 83518.968 | N4: =$K4+N23*L4 -> 81303.23
A5: Expenses | B5: =SUM('Data Sheet'!B18,'Data Sheet'!B20:B24, -1*'Data Sheet'!B19) -> 24660.61 | C5: =SUM('Data Sheet'!C18,'Data Sheet'!C20:C24, -1*'Data Sheet'!C19) -> 27298.09 | D5: =SUM('Data Sheet'!D18,'Data Sheet'!D20:D24, -1*'Data Sheet'!D19) -> 26928.35 | E5: =SUM('Data Sheet'!E18,'Data Sheet'!E20:E24, -1*'Data Sheet'!E19) -> 29802.19 | F5: =SUM('Data Sheet'!F18,'Data Sheet'!F20:F24, -1*'Data Sheet'!F19) -> 30044.16 | G5: =SUM('Data Sheet'!G18,'Data Sheet'!G20:G24, -1*'Data Sheet'!G19) -> 32192.67 | H5: =SUM('Data Sheet'!H18,'Data Sheet'!H20:H24, -1*'Data Sheet'!H19) -> 40021.39 | I5: =SUM('Data Sheet'!I18,'Data Sheet'!I20:I24, -1*'Data Sheet'!I19) -> 45214.77 | ... K5: =SUM('Data Sheet'!K18,'Data Sheet'!K20:K24, -1*'Data Sheet'!K19) -> 49483.89 | L5: =SUM(Quarters!H5:K5) -> 52895.65 | M5: =M4-M6 -> 53597.014 | N5: =N4-N6 -> 53886.182
A6: Operating Profit | B6: =B4-B5 -> 14531.49 | C6: =C4-C5 -> 15469.51 | D6: =D4-D5 -> 16520.59 | E6: =E4-E5 -> 18537.39 | F6: =F4-F5 -> 19343.54 | G6: =G4-G5 -> 17064.78 | H6: =H4-H5 -> 20623.15 | I6: =I4-I5 -> 25704.26 | ... K6: =K4-K5 -> 25839.45 | L6: =SUM(Quarters!H6:K6) -> 26913.07 | M6: =M4*M24 -> 29921.955 | N6: =N4*N24 -> 27417.048
A7: Other Income | B7: ='Data Sheet'!B25 -> 1483.11 | C7: ='Data Sheet'!C25 -> 1758.63 | D7: ='Data Sheet'!D25 -> 2239.81 | E7: ='Data Sheet'!E25 -> 2080.44 | F7: ='Data Sheet'!F25 -> 2417.32 | G7: ='Data Sheet'!G25 -> 2576.95 | H7: ='Data Sheet'!H25 -> 1909.72 | I7: ='Data Sheet'!I25 -> 2097.64 | ... K7: ='Data Sheet'!K25 -> 17794.88 | L7: =SUM(Quarters!H7:K7) -> 17202.94 | M7: 0 | N7: 0
A8: Depreciation | B8: ='Data Sheet'!B26 -> 1077.4 | C8: ='Data Sheet'!C26 -> 1152.79 | D8: ='Data Sheet'!D26 -> 1236.28 | E8: ='Data Sheet'!E26 -> 1396.61 | F8: ='Data Sheet'!F26 -> 1644.91 | G8: ='Data Sheet'!G26 -> 1645.59 | H8: ='Data Sheet'!H26 -> 1732.41 | I8: ='Data Sheet'!I26 -> 1809.01 | ... K8: ='Data Sheet'!K26 -> 1646.32 | L8: =SUM(Quarters!H8:K8) -> 1699.61 | M8: =+$L8 -> 1699.61 | N8: =+$L8 -> 1699.61
A9: Interest | B9: ='Data Sheet'!B27 -> 78.13 | C9: ='Data Sheet'!C27 -> 49.03 | D9: ='Data Sheet'!D27 -> 115.01 | E9: ='Data Sheet'!E27 -> 71.4 | F9: ='Data Sheet'!F27 -> 81.38 | G9: ='Data Sheet'!G27 -> 57.97 | H9: ='Data Sheet'!H27 -> 59.99 | I9: ='Data Sheet'!I27 -> 77.77 | ... K9: ='Data Sheet'!K27 -> 45.06 | L9: =SUM(Quarters!H9:K9) -> 66.9 | M9: =+$L9 -> 66.9 | N9: =+$L9 -> 66.9
A10: Profit before tax | B10: ='Data Sheet'!B28 -> 14859.07 | C10: ='Data Sheet'!C28 -> 16026.32 | D10: ='Data Sheet'!D28 -> 17409.11 | E10: ='Data Sheet'!E28 -> 19149.82 | F10: ='Data Sheet'!F28 -> 20034.57 | G10: ='Data Sheet'!G28 -> 17938.17 | H10: ='Data Sheet'!H28 -> 20740.47 | I10: ='Data Sheet'!I28 -> 25915.12 | ... K10: ='Data Sheet'!K28 -> 41942.95 | L10: =SUM(Quarters!H10:K10) -> 42349.5 | M10: =M6+M7-SUM(M8:M9) -> 28155.445 | N10: =N6+N7-SUM(N8:N9) -> 25650.538
A11: Tax | B11: ='Data Sheet'!B29 -> 5358.21 | C11: ='Data Sheet'!C29 -> 5549.09 | D11: ='Data Sheet'!D29 -> 5916.43 | E11: ='Data Sheet'!E29 -> 6313.92 | F11: ='Data Sheet'!F29 -> 4441.79 | G11: ='Data Sheet'!G29 -> 4555.29 | H11: ='Data Sheet'!H29 -> 5237.34 | I11: ='Data Sheet'!I29 -> 6438.4 | ... K11: ='Data Sheet'!K29 -> 6890.47 | L11: =SUM(Quarters!H11:K11) -> 6993.21 | M11: =IF($L10>0,$L11/$L10,0) -> 0.16513088 | N11: =IF($L10>0,$L11/$L10,0) -> 0.16513088
A12: Net profit | B12: ='Data Sheet'!B30 -> 9344.45 | C12: ='Data Sheet'!C30 -> 10289.44 | D12: ='Data Sheet'!D30 -> 11271.2 | E12: ='Data Sheet'!E30 -> 12592.33 | F12: ='Data Sheet'!F30 -> 15306.23 | G12: ='Data Sheet'!G30 -> 13161.19 | H12: ='Data Sheet'!H30 -> 15242.66 | I12: ='Data Sheet'!I30 -> 19191.66 | ... K12: ='Data Sheet'!K30 -> 34746.63 | L12: =SUM(Quarters!H12:K12) -> 35028.87 | M12: =M10-M11*M10 -> 23506.111 | N12: =N10-N11*N10 -> 21414.842
A13: EPS | B13: =IF('Data Sheet'!B93>0,B12/'Data Sheet'!B93,0) -> 7.7413676 | C13: =IF('Data Sheet'!C93>0,C12/'Data Sheet'!C93,0) -> 8.4704875 | D13: =IF('Data Sheet'!D93>0,D12/'Data Sheet'!D93,0) -> 9.2354334 | E13: =IF('Data Sheet'!E93>0,E12/'Data Sheet'!E93,0) -> 10.272242 | F13: =IF('Data Sheet'!F93>0,F12/'Data Sheet'!F93,0) -> 12.451986 | G13: =IF('Data Sheet'!G93>0,G12/'Data Sheet'!G93,0) -> 10.692505 | H13: =IF('Data Sheet'!H93>0,H12/'Data Sheet'!H93,0) -> 12.368976 | I13: =IF('Data Sheet'!I93>0,I12/'Data Sheet'!I93,0) -> 15.442276 | ... K13: =IF('Data Sheet'!K93>0,K12/'Data Sheet'!K93,0) -> 27.765984 | L13: =IF('Data Sheet'!$B6>0,'Profit & Loss'!L12/'Data Sheet'!$B6,0) -> 27.957188 | M13: =IF('Data Sheet'!$B6>0,'Profit & Loss'!M12/'Data Sheet'!$B6,0) -> 18.760661 | N13: =IF('Data Sheet'!$B6>0,'Profit & Loss'!N12/'Data Sheet'!$B6,0) -> 17.091581
A14: Price to earning | B14: =IF(B15>0,B15/B13,"") -> 26.497902 | C14: =IF(C15>0,C15/C13,"") -> 31.019466 | D14: =IF(D15>0,D15/D13,"") -> 25.93273 | E14: =IF(E15>0,E15/E13,"") -> 27.12553 | F14: =IF(F15>0,F15/F13,"") -> 12.925649 | G14: =IF(G15>0,G15/G13,"") -> 19.155475 | H14: =IF(H15>0,H15/H13,"") -> 18.995914 | I14: =IF(I15>0,I15/I13,"") -> 23.2796 | ... K14: =IF(K15>0,K15/K13,"") -> 14.757266 | L14: =IF(L13>0,L15/L13,0) -> 11.319093 | M14: =M25 -> 18.464699 | N14: =N25 -> 11.319093
A15: Price | B15: ='Data Sheet'!B90 -> 205.13 | C15: ='Data Sheet'!C90 -> 262.75 | D15: ='Data Sheet'!D90 -> 239.5 | E15: ='Data Sheet'!E90 -> 278.64 | F15: ='Data Sheet'!F90 -> 160.95 | G15: ='Data Sheet'!G90 -> 204.82 | H15: ='Data Sheet'!H90 -> 234.96 | I15: ='Data Sheet'!I90 -> 359.49 | ... K15: ='Data Sheet'!K90 -> 409.75 | L15: ='Data Sheet'!B8 -> 316.45 | M15: =M13*M14 -> 346.40996 | N15: =N13*N14 -> 193.46119
A17: RATIOS:
A18: Dividend Payout | B18: =IF('Data Sheet'!B30>0, 'Data Sheet'!B31/'Data Sheet'!B30, 0) -> 0.73199814 | C18: =IF('Data Sheet'!C30>0, 'Data Sheet'!C31/'Data Sheet'!C30, 0) -> 0.56077104 | D18: =IF('Data Sheet'!D30>0, 'Data Sheet'!D31/'Data Sheet'!D30, 0) -> 0.5576345 | E18: =IF('Data Sheet'!E30>0, 'Data Sheet'!E31/'Data Sheet'!E30, 0) -> 0.55976138 | F18: =IF('Data Sheet'!F30>0, 'Data Sheet'!F31/'Data Sheet'!F30, 0) -> 0.81513083 | G18: =IF('Data Sheet'!G30>0, 'Data Sheet'!G31/'Data Sheet'!G30, 0) -> 1.0053772 | H18: =IF('Data Sheet'!H30>0, 'Data Sheet'!H31/'Data Sheet'!H30, 0) -> 0.92974586 | I18: =IF('Data Sheet'!I30>0, 'Data Sheet'!I31/'Data Sheet'!I30, 0) -> 1.0037381 | ... K18: =IF('Data Sheet'!K30>0, 'Data Sheet'!K31/'Data Sheet'!K30, 0) -> 0.51681933
A19: OPM | B19: =IF(B6>0,B6/B4,0) -> 0.370776 | C19: =IF(C6>0,C6/C4,0) -> 0.36171097 | D19: =IF(D6>0,D6/D4,0) -> 0.38022999 | E19: =IF(E6>0,E6/E4,0) -> 0.38348265 | F19: =IF(F6>0,F6/F4,0) -> 0.39166716 | G19: =IF(G6>0,G6/G4,0) -> 0.34644059 | H19: =IF(H6>0,H6/H4,0) -> 0.34006606 | I19: =IF(I6>0,I6/I4,0) -> 0.36244517 | ... L19: =IF(L6>0,L6/L4,0) -> 0.33721967
G22: TRENDS: | H22: 10 YEARS | I22: 7 YEARS | J22: 5 YEARS | K22: 3 YEARS | L22: RECENT | M22: BEST | N22: WORST
G23: Sales Growth | H23: =IF(B4=0,"",POWER($K4/B4,1/9)-1) -> 0.075290157 | I23: =IF(D4=0,"",POWER($K4/D4,1/7)-1) -> 0.081772082 | J23: =IF(F4=0,"",POWER($K4/F4,1/5)-1) -> 0.088083322 | K23: =IF(H4=0,"",POWER($K4/H4, 1/3)-1) -> 0.074927782 | L23: =IF(ISERROR(MAX(IF(J4=0,"",(K4-J4)/J4),IF(K4=0,"",(L4-K4)/K4))),"",MAX(IF(J4=0,"",(K4-J4)/J4),IF(K4=0,"",(L4-K4)/K4))) -> 0.10880596 | M23: =MAX(K23:L23) -> 0.10880596 | N23: =MIN(H23:L23) -> 0.074927782
G24: OPM | H24: =IF(SUM(B4:$K$4)=0,"",SUMPRODUCT(B19:$K$19,B4:$K$4)/SUM(B4:$K$4)) -> 0.36333562 | I24: =IF(SUM(E4:$K$4)=0,"",SUMPRODUCT(E19:$K$19,E4:$K$4)/SUM(E4:$K$4)) -> 0.36106877 | J24: =IF(SUM(G4:$K$4)=0,"",SUMPRODUCT(G19:$K$19,G4:$K$4)/SUM(G4:$K$4)) -> 0.35306244 | K24: =IF(SUM(I4:$K$4)=0, "", SUMPRODUCT(I19:$K$19,I4:$K$4)/SUM(I4:$K$4)) -> 0.35826538 | L24: =L19 -> 0.33721967 | M24: =MAX(K24:L24) -> 0.35826538 | N24: =MIN(H24:L24) -> 0.33721967
G25: Price to Earning | H25: =IF(ISERROR(AVERAGEIF(B14:$L14,">0")),"",AVERAGEIF(B14:$L14,">0")) -> 21.410133 | I25: =IF(ISERROR(AVERAGEIF(E14:$L14,">0")),"",AVERAGEIF(E14:$L14,">0")) -> 19.007671 | J25: =IF(ISERROR(AVERAGEIF(G14:$L14,">0")),"",AVERAGEIF(G14:$L14,">0")) -> 18.668364 | K25: =IF(ISERROR(AVERAGEIF(I14:$L14,">0")),"",AVERAGEIF(I14:$L14,">0")) -> 18.464699 | L25: =L14 -> 11.319093 | M25: =MAX(K25:L25) -> 18.464699 | N25: =MIN(H25:L25) -> 11.319093
A27: Sales Growth y-o-y | C27: =C4/B4-1 -> 0.09123012 | D27: =D4/C4-1 -> 0.015931219 | E27: =E4/D4-1 -> 0.11256063 | F27: =F4/E4-1 -> 0.021682439 | G27: =G4/F4-1 -> -0.0026372963 | H27: =H4/G4-1 -> 0.23117498 | I27: =I4/H4-1 -> 0.16942152 | J27: =J4/I4-1 -> -0.042119724 | K27: =K4/J4-1 -> 0.10880596
A29: Gross Profit | E29: ='Data Sheet'!E17-'Data Sheet'!E18-'Data Sheet'!E19-'Data Sheet'!E20-'Data Sheet'!E21 -> 27895.13 | F29: ='Data Sheet'!F17-'Data Sheet'!F18-'Data Sheet'!F19-'Data Sheet'!F20-'Data Sheet'!F21 -> 27946.83 | G29: ='Data Sheet'!G17-'Data Sheet'!G18-'Data Sheet'!G19-'Data Sheet'!G20-'Data Sheet'!G21 -> 25548.73 | H29: ='Data Sheet'!H17-'Data Sheet'!H18-'Data Sheet'!H19-'Data Sheet'!H20-'Data Sheet'!H21 -> 30110.03 | I29: ='Data Sheet'!I17-'Data Sheet'!I18-'Data Sheet'!I19-'Data Sheet'!I20-'Data Sheet'!I21 -> 37635.94 | J29: ='Data Sheet'!J17-'Data Sheet'!J18-'Data Sheet'!J19-'Data Sheet'!J20-'Data Sheet'!J21 -> 37078.94 | K29: ='Data Sheet'!K17-'Data Sheet'!K18-'Data Sheet'!K19-'Data Sheet'!K20-'Data Sheet'!K21 -> 38572.61
A30: GPM | E30: =E29/E4 -> 0.57706604 | F30: =F29/F4 -> 0.5658662 | G30: =G29/G4 -> 0.51867748 | H30: =H29/H4 -> 0.49650026 | I30: =I29/I4 -> 0.53068887 | J30: =J29/J4 -> 0.54582484 | K30: =K29/K4 -> 0.51209373
A32: EBITDA Margins | B32: =B6/B4 -> 0.370776 | C32: =C6/C4 -> 0.36171097 | D32: =D6/D4 -> 0.38022999 | E32: =E6/E4 -> 0.38348265 | F32: =F6/F4 -> 0.39166716 | G32: =G6/G4 -> 0.34644059 | H32: =H6/H4 -> 0.34006606 | I32: =I6/I4 -> 0.36244517 | ... K32: =K6/K4 -> 0.34304706
A34: EBIT Margins | B34: =(B6-B8)/B4 -> 0.34328576 | C34: =(C6-C8)/C4 -> 0.33475622 | D34: =(D6-D8)/D4 -> 0.35177636 | E34: =(E6-E8)/E4 -> 0.354591 | F34: =(F6-F8)/F4 -> 0.35836109 | G34: =(G6-G8)/G4 -> 0.31303265 | H34: =(H6-H8)/H4 -> 0.31149944 | I34: =(I6-I8)/I4 -> 0.33693707 | ... K34: =(K6-K8)/K4 -> 0.32119035
A36: Net Profit Margins | B36: =B12/B4 -> 0.23842688 | C36: =C12/C4 -> 0.24058961 | D36: =D12/D4 -> 0.25941254 | E36: =E12/E4 -> 0.2604973 | F36: =F12/F4 -> 0.30991988 | G36: =G12/G4 -> 0.26719187 | H36: =H12/H4 -> 0.25134431 | I36: =I12/I4 -> 0.27061368 | ... K36: =K12/K4 -> 0.46129964
A38: EPS Growth | C38: =C13/B13-1 -> 0.094184898 | D38: =D13/C13-1 -> 0.090307187 | E38: =E13/D13-1 -> 0.11226415 | F38: =F13/E13-1 -> 0.21219753 | G38: =G13/F13-1 -> -0.14130126 | H38: =H13/G13-1 -> 0.15678939 | I38: =I13/H13-1 -> 0.2484684 | J38: =J13/I13-1 -> 0.0611831 | K38: =K13/J13-1 -> 0.69438246
A40: Dividend per share | B40: =B13*B18 -> 5.6666667 | C40: =C13*C18 -> 4.7500041 | D40: =D13*D18 -> 5.1499963 | E40: =E13*E18 -> 5.7500041 | F40: =F13*F18 -> 10.149998 | G40: =G13*G18 -> 10.75 | H40: =H13*H18 -> 11.500004 | I40: =I13*I18 -> 15.5 | ... K40: =K13*K18 -> 14.349997
A41: Dividend Growth | C41: =C40/B40-1 -> -0.16176398 | D41: =D40/C40-1 -> 0.084208811 | E41: =E40/D40-1 -> 0.11650645 | F41: =F40/E40-1 -> 0.76521571 | G41: =G40/F40-1 -> 0.059113555 | H41: =H40/G40-1 -> 0.069767819 | I41: =I40/H40-1 -> 0.34782561 | J41: =J40/I40-1 -> -0.11290335 | K41: =K40/J40-1 -> 0.043636312
A44: Market Capitalization | E44: ='Data Sheet'!E90*'Data Sheet'!E93 -> 341573.63 | F44: ='Data Sheet'!F90*'Data Sheet'!F93 -> 197842.96 | G44: ='Data Sheet'!G90*'Data Sheet'!G93 -> 252108.84 | H44: ='Data Sheet'!H90*'Data Sheet'!H93 -> 289548.26 | I44: ='Data Sheet'!I90*'Data Sheet'!I93 -> 446774.17 | J44: ='Data Sheet'!J90*'Data Sheet'!J93 -> 501298.16 | K44: ='Data Sheet'!K90*'Data Sheet'!K93 -> 512765.25
A45: Debt | E45: ='Balance Sheet'!E6 -> 13.44 | F45: ='Balance Sheet'!F6 -> 277.45 | G45: ='Balance Sheet'!G6 -> 270.83 | H45: ='Balance Sheet'!H6 -> 249.44 | I45: ='Balance Sheet'!I6 -> 306.04 | J45: ='Balance Sheet'!J6 -> 303.43 | K45: ='Balance Sheet'!K6 -> 284.54
A46: Cash | E46: ='Data Sheet'!E69 -> 4152.03 | F46: ='Data Sheet'!F69 -> 7277.34 | G46: ='Data Sheet'!G69 -> 4659.02 | H46: ='Data Sheet'!H69 -> 4654.42 | I46: ='Data Sheet'!I69 -> 4880.19 | J46: ='Data Sheet'!J69 -> 7217.68 | K46: ='Data Sheet'!K69 -> 4012.36
A47: EV | E47: =E44+E45-E46 -> 337435.04 | F47: =F44+F45-F46 -> 190843.07 | G47: =G44+G45-G46 -> 247720.65 | H47: =H44+H45-H46 -> 285143.28 | I47: =I44+I45-I46 -> 442200.02 | J47: =J44+J45-J46 -> 494383.91 | K47: =K44+K45-K46 -> 509037.43
A49: EV/EBITDA | E49: =E47/E6 -> 18.202942 | F49: =F47/F6 -> 9.8659847 | G49: =G47/G6 -> 14.516487 | H49: =H47/H6 -> 13.826369 | I49: =I47/I6 -> 17.203375 | J49: =J47/J6 -> 19.628122 | K49: =K47/K6 -> 19.70001
A50: EV/Sales | E50: =E47/E4 -> 6.9805125 | F50: =F47/F4 -> 3.8641822 | G50: =G47/G4 -> 5.0291002 | H50: =H47/H4 -> 4.7018788 | I50: =I47/I4 -> 6.2352802 | J50: =J47/J4 -> 7.2776357 | K50: =K47/K4 -> 6.7580305
A52: P/B | E52: =E44/'Balance Sheet'!E26 -> 5.7755936 | F52: =F44/'Balance Sheet'!F26 -> 3.0309955 | G52: =G44/'Balance Sheet'!G26 -> 4.1776297 | H52: =H44/'Balance Sheet'!H26 -> 4.6360678 | I52: =I44/'Balance Sheet'!I26 -> 6.460451 | J52: =J44/'Balance Sheet'!J26 -> 6.7282022 | K52: =K44/'Balance Sheet'!K26 -> 7.3220746

Sheet Data Sheet
A1: COMPANY NAME | B1: ITC LTD | E1: ITC LTD
A2: LATEST VERSION | B2: 2.1 | E2: PLEASE DO NOT MAKE ANY CHANGES TO THIS SHEET
A3: CURRENT VERSION | B3: 2.1
A5: META
A6: Number of shares | B6: =IF(B9>0, B9/B8, 0) -> 1252.9468
A7: Face Value | B7: 1
A8: Current Price | B8: 316.45
A9: Market Capitalization | B9: 396495.03
A15: PROFIT & LOSS
A16: Report Date | B16: 42460 | C16: 42825 | D16: 43190 | E16: 43555 | F16: 43921 | G16: 44286 | H16: 44651 | I16: 45016 | J16: 45382 | K16: 45747
A17: Sales | B17: 39192.1 | C17: 42767.6 | D17: 43448.94 | E17: 48339.58 | F17: 49387.7 | G17: 49257.45 | H17: 60644.54 | I17: 70919.03 | J17: 67931.94 | K17: 75323.34
A18: Raw Material Cost | B18: 13763.88 | C18: 15456.59 | D18: 14827.72 | E18: 17623.52 | F18: 18048.6 | G18: 20776.71 | H18: 27071.07 | I18: 29364.36 | J18: 27348.57 | K18: 32704.37
A19: Change in Inventory | B19: 195.38 | C19: -592.57 | D19: -1027.76 | E19: 203.19 | F19: 703.13 | G19: 645.27 | H19: 686 | I19: 358.59 | J19: 367.77 | K19: 725.65
A20: Power and Fuel | B20: 571.88 | C20: 584.33 | D20: 653.5 | E20: 746.73 | F20: 780.85 | G20: 699.56 | H20: 889.77 | I20: 1232.34 | J20: 952.9 | K20: 975.35
A21: Other Mfr. Exp | B21: 1581.59 | C21: 1683.9 | D21: 1697.62 | E21: 1871.01 | F21: 1908.29 | G21: 1587.18 | H21: 1887.67 | I21: 2327.8 | J21: 2183.76 | K21: 2345.36
A22: Employee Cost | B22: 3440.97 | C22: 3631.73 | D22: 3760.9 | E22: 4177.88 | F22: 4295.79 | G22: 4463.33 | H22: 4890.55 | I22: 5736.22 | J22: 5548.53 | K22: 6169.78
A23: Selling and admin | B23: 4261.78 | C23: 4179.74 | D23: 3954.87 | E23: 4546.39 | F23: 4488.63 | G23: 4236.77 | H23: 4858.38 | I23: 5604.08 | J23: 5312.45 | K23: 5793.29
A24: Other Expenses | B24: 1235.89 | C24: 1169.23 | D24: 1005.98 | E24: 1039.85 | F24: 1225.13 | G24: 1074.39 | H24: 1109.95 | I24: 1308.56 | J24: 1765.97 | K24: 2221.39
A25: Other Income | B25: 1483.11 | C25: 1758.63 | D25: 2239.81 | E25: 2080.44 | F25: 2417.32 | G25: 2576.95 | H25: 1909.72 | I25: 2097.64 | J25: 3330.45 | K25: 17794.88
A26: Depreciation | B26: 1077.4 | C26: 1152.79 | D26: 1236.28 | E26: 1396.61 | F26: 1644.91 | G26: 1645.59 | H26: 1732.41 | I26: 1809.01 | J26: 1518.05 | K26: 1646.32
A27: Interest | B27: 78.13 | C27: 49.03 | D27: 115.01 | E27: 71.4 | F27: 81.38 | G27: 57.97 | H27: 59.99 | I27: 77.77 | J27: 39.11 | K27: 45.06
... A31: Dividend Amount | B31: 6840.12 | C31: 5770.02 | D31: 6285.21 | E31: 7048.7 | F31: 12476.58 | G31: 13231.96 | H31: 14171.8 | I31: 19263.4 | J31: 17166.46 | K31: 17957.73
A40: Quarters
A41: Report Date | B41: 45199 | C41: 45291 | D41: 45382 | E41: 45473 | F41: 45565 | G41: 45657 | H41: 45747 | I41: 45838 | J41: 45930 | K41: 46022
A42: Sales | B42: 17774.47 | C42: 17195.24 | D42: 17037.8 | E42: 17777.81 | F42: 19990.36 | G42: 18790.17 | H42: 18765 | I42: 21494.79 | J42: 19501.63 | K42: 20047.3
A43: Expenses | B43: 11320.23 | C43: 10985.01 | D43: 10735.73 | E43: 11232.97 | F43: 13438.28 | G43: 12428.27 | H43: 12245.61 | I43: 14678.32 | J43: 12806.94 | K43: 13164.78
A44: Other Income | B44: 673.5 | C44: 820.26 | D44: 868 | E44: 771.13 | F44: 690.31 | G44: 803.4 | H44: 15391.28 | I44: 750.97 | J44: 738.84 | K44: 321.85
A45: Depreciation | B45: 453.04 | C45: 384.04 | D45: 385.09 | E45: 403.13 | F45: 416.18 | G45: 415.98 | H45: 411.03 | I45: 422.96 | J45: 434.8 | K45: 430.82
A46: Interest | B46: 9.87 | C46: 11.94 | D46: 10.72 | E46: 9.6 | F46: 14.73 | G46: 9.82 | H46: 10.91 | I46: 16.47 | J46: 20.05 | K46: 19.47
A47: Profit before tax | B47: 6664.83 | C47: 6634.51 | D47: 6774.26 | E47: 6903.24 | F47: 6811.48 | G47: 6739.5 | H47: 21488.73 | I47: 7128.01 | J47: 6978.68 | K47: 6754.08
A48: Tax | B48: 1700.31 | C48: 1227.99 | D48: 1583.55 | E48: 1726.25 | F48: 1757.05 | G48: 1726.32 | H48: 1680.85 | I48: 1784.6 | J48: 1792.13 | K48: 1735.63
A49: Net profit | B49: 4898.07 | C49: 5335.23 | D49: 5120.55 | E49: 5091.59 | F49: 4992.87 | G49: 4934.8 | H49: 19727.37 | I49: 5244.2 | J49: 5126.11 | K49: 4931.19
A50: Operating Profit | B50: 6454.24 | C50: 6210.23 | D50: 6302.07 | E50: 6544.84 | F50: 6552.08 | G50: 6361.9 | H50: 6519.39 | I50: 6816.47 | J50: 6694.69 | K50: 6882.52
A55: BALANCE SHEET
A56: Report Date | B56: 42460 | C56: 42825 | D56: 43190 | E56: 43555 | F56: 43921 | G56: 44286 | H56: 44651 | I56: 45016 | J56: 45382 | K56: 45747
A57: Equity Share Capital | B57: 804.72 | C57: 1214.74 | D57: 1220.43 | E57: 1225.86 | F57: 1229.22 | G57: 1230.88 | H57: 1232.33 | I57: 1242.8 | J57: 1248.47 | K57: 1251.41
A58: Reserves | B58: 41874.8 | C58: 45198.19 | D58: 51289.68 | E58: 57915.01 | F58: 64044.04 | G58: 59116.46 | H58: 61223.24 | I58: 67912.46 | J58: 73258.53 | K58: 68778.64
A59: Borrowings | B59: 83.78 | C59: 45.72 | D59: 35.92 | E59: 13.44 | F59: 277.45 | G59: 270.83 | H59: 249.44 | I59: 306.04 | J59: 303.43 | K59: 284.54
A60: Other Liabilities | B60: 8888.04 | C60: 9439.67 | D60: 11694.85 | E60: 12584.73 | F60: 11760.04 | G60: 13142.59 | H60: 14491.01 | I60: 16369.66 | J60: 16943.54 | K60: 17688.11
A61: Total | B61: 51651.34 | C61: 55898.32 | D61: 64240.88 | E61: 71739.04 | F61: 77310.75 | G61: 73760.76 | H61: 77196.02 | I61: 85830.96 | J61: 91753.97 | K61: 88002.7
...

Sheet Teaser
B1: =UPDATE&" - One Page Profile" -> ITC LTD - One Page Profile
C3: ='Input Sheet'!C5 -> ITC Limited is an Indian conglomerate, headquartered in Kolkata.[10] It has a presence across six business segments, namely FMCG, agribusiness, information technology, paper products, and packaging.[11] It generates a plurality of its revenue from tobacco products.
B4: INR (Crs)
B5: Key Financial Metrics | C5: 44286 | D5: 44651 | E5: 45016 | F5: 45382 | G5: 45747 | I5: Share Price - 5Y
B7: Total Sales | C7: ='Profit & Loss'!G4 -> 49257.45 | D7: ='Profit & Loss'!H4 -> 60644.54 | E7: ='Profit & Loss'!I4 -> 70919.03 | F7: ='Profit & Loss'!J4 -> 67931.94 | G7: ='Profit & Loss'!K4 -> 75323.34
B8: Sales Growth (y-o-y) | C8: ='Profit & Loss'!G27 -> -0.0026372963 | D8: ='Profit & Loss'!H27 -> 0.23117498 | E8: ='Profit & Loss'!I27 -> 0.16942152 | F8: ='Profit & Loss'!J27 -> -0.042119724 | G8: ='Profit & Loss'!K27 -> 0.10880596
B9: Gross Profit Margins (%) | C9: ='Profit & Loss'!G30 -> 0.51867748 | D9: ='Profit & Loss'!H30 -> 0.49650026 | E9: ='Profit & Loss'!I30 -> 0.53068887 | F9: ='Profit & Loss'!J30 -> 0.54582484 | G9: ='Profit & Loss'!K30 -> 0.51209373
B10: EBITDA Margins (%) | C10: ='Profit & Loss'!G32 -> 0.34644059 | D10: ='Profit & Loss'!H32 -> 0.34006606 | E10: ='Profit & Loss'!I32 -> 0.36244517 | F10: ='Profit & Loss'!J32 -> 0.37077596 | G10: ='Profit & Loss'!K32 -> 0.34304706
B11: EBIT Margins (%) | C11: ='Profit & Loss'!G34 -> 0.31303265 | D11: ='Profit & Loss'!H34 -> 0.31149944 | E11: ='Profit & Loss'!I34 -> 0.33693707 | F11: ='Profit & Loss'!J34 -> 0.34842932 | G11: ='Profit & Loss'!K34 -> 0.32119035
B12: Net Profit Margins (%) | C12: ='Profit & Loss'!G36 -> 0.26719187 | D12: ='Profit & Loss'!H36 -> 0.25134431 | E12: ='Profit & Loss'!I36 -> 0.27061368 | F12: ='Profit & Loss'!J36 -> 0.30116584 | G12: ='Profit & Loss'!K36 -> 0.46129964
B13: Earnings Per Share (in Rs) | C13: =Annual[[#This Row],[Column7]] -> 10.692505 | D13: =Annual[[#This Row],[Column8]] -> 12.368976 | E13: =Annual[[#This Row],[Column9]] -> 15.442276 | F13: =Annual[[#This Row],[Column10]] -> 16.387082 | G13: =Annual[[#This Row],[Column11]] -> 27.765984
B14: EPS Growth (y-o-y) | C14: ='Profit & Loss'!G38 -> -0.14130126 | D14: ='Profit & Loss'!H38 -> 0.15678939 | E14: ='Profit & Loss'!I38 -> 0.2484684 | F14: ='Profit & Loss'!J38 -> 0.0611831 | G14: ='Profit & Loss'!K38 -> 0.69438246
B15: Dividend Per Share (in Rs) | C15: ='Profit & Loss'!G40 -> 10.75 | D15: ='Profit & Loss'!H40 -> 11.500004 | E15: ='Profit & Loss'!I40 -> 15.5 | F15: ='Profit & Loss'!J40 -> 13.749998 | G15: ='Profit & Loss'!K40 -> 14.349997
B16: DPS Growth (y-o-y) | C16: ='Profit & Loss'!G41 -> 0.059113555 | D16: ='Profit & Loss'!H41 -> 0.069767819 | E16: ='Profit & Loss'!I41 -> 0.34782561 | F16: ='Profit & Loss'!J41 -> -0.11290335 | G16: ='Profit & Loss'!K41 -> 0.043636312
B18: Key Financial Ratios | C18: 44286 | D18: 44651 | E18: 45016 | F18: 45382 | G18: 45747 | I18: Volume - 5Y
B20: Price to Earnings | C20: ='Profit & Loss'!G14 -> 19.155475 | D20: ='Profit & Loss'!H14 -> 18.995914 | E20: ='Profit & Loss'!I14 -> 23.2796 | F20: ='Profit & Loss'!J14 -> 24.502837 | G20: ='Profit & Loss'!K14 -> 14.757266
B21: EV/EBITDA | C21: ='Profit & Loss'!G49 -> 14.516487 | D21: ='Profit & Loss'!H49 -> 13.826369 | E21: ='Profit & Loss'!I49 -> 17.203375 | F21: ='Profit & Loss'!J49 -> 19.628122 | G21: ='Profit & Loss'!K49 -> 19.70001
B22: EV/Sales | C22: ='Profit & Loss'!G50 -> 5.0291002 | D22: ='Profit & Loss'!H50 -> 4.7018788 | E22: ='Profit & Loss'!I50 -> 6.2352802 | F22: ='Profit & Loss'!J50 -> 7.2776357 | G22: ='Profit & Loss'!K50 -> 6.7580305
B23: Price to Book Value | C23: ='Profit & Loss'!G52 -> 4.1776297 | D23: ='Profit & Loss'!H52 -> 4.6360678 | E23: ='Profit & Loss'!I52 -> 6.460451 | F23: ='Profit & Loss'!J52 -> 6.7282022 | G23: ='Profit & Loss'!K52 -> 7.3220746
B24: Return on Equity (%) | C24: ='Balance Sheet'!G23 -> 0.21809064 | D24: ='Balance Sheet'!H23 -> 0.24405605 | E24: ='Balance Sheet'!I23 -> 0.27751555 | F24: ='Balance Sheet'!J23 -> 0.2745887 | G24: ='Balance Sheet'!K23 -> 0.49616743
B25: Return on Capital Employed (%) | C25: ='Balance Sheet'!G24 -> 0.28527066 | D25: ='Balance Sheet'!H24 -> 0.33733253 | E25: ='Balance Sheet'!I24 -> 0.39333609 | F25: ='Balance Sheet'!J24 -> 0.37429273 | G25: ='Balance Sheet'!K24 -> 0.57864605
B27: Top 10 Shareholders | C27: ='Share Price'!H31 -> N. Shares (in Crs) | D27: ='Share Price'!I31 -> % Holding | E27: ='Share Price'!J31 -> Market Value (in Crs) | I27: Shareholding Pattern
B28: ='Share Price'!G32 -> Tobacco Manufacturers (India) Limited | C28: ='Share Price'!H32 -> 222.84959 | D28: =('Share Price'!I32)/100 -> 0.1779 | E28: ='Share Price'!J32 -> 70197.62
B29: ='Share Price'!G33 -> Life Insurance Corporation of India | C29: ='Share Price'!H33 -> 198.32053 | D29: =('Share Price'!I33)/100 -> 0.1583 | E29: ='Share Price'!J33 -> 62470.965
B30: ='Share Price'!G34 -> Specified Undertaking of the Unit Trust of India | C30: ='Share Price'!H34 -> 97.453143 | D30: =('Share Price'!I34)/100 -> 0.0778 | E30: ='Share Price'!J34 -> 30697.74
B31: ='Share Price'!G35 -> Myddleton Investment Company Limited | C31: ='Share Price'!H35 -> 48.631194 | D31: =('Share Price'!I35)/100 -> 0.0388 | E31: ='Share Price'!J35 -> 15318.826
B32: ='Share Price'!G36 -> ICICI Prudential Mutual Funds | C32: ='Share Price'!H36 -> 44.801726 | D32: =('Share Price'!I36)/100 -> 0.0358 | E32: ='Share Price'!J36 -> 14112.544
B33: ='Share Price'!G37 -> SBI Mutual Funds | C33: ='Share Price'!H37 -> 41.263847 | D33: =('Share Price'!I37)/100 -> 0.0329 | E33: ='Share Price'!J37 -> 12998.112
B34: ='Share Price'!G38 -> QIB - Insurance Company Registered | C34: ='Share Price'!H38 -> 26.370496 | D34: =('Share Price'!I38)/100 -> 0.0211 | E34: ='Share Price'!J38 -> 8306.7064
B35: ='Share Price'!G39 -> Parag Parikh Flexi Cap Mutual Funds | C35: ='Share Price'!H39 -> 23.861659 | D35: =('Share Price'!I39)/100 -> 0.019 | E35: ='Share Price'!J39 -> 7516.4227
B36: ='Share Price'!G40 -> Goldman Sachs Trust II - Goldman Sachs GQG Partners International Opportunities Fund | C36: ='Share Price'!H40 -> 21.766939 | D36: =('Share Price'!I40)/100 -> 0.0174 | E36: ='Share Price'!J40 -> 6856.5857
B37: ='Share Price'!G41 -> General Insurance Corporation of India | C37: ='Share Price'!H41 -> 21.718551 | D37: =('Share Price'!I41)/100 -> 0.0173 | E37: ='Share Price'!J41 -> 6841.3435
B39: Managerial Remuneration | C39: Designation | D39: Remuneration | E39: X of Median Salary | I39: Capital Structure
B41: Mr. Sanjeev Puri | C41: CMD | D41: 25.66 | F41: 377 | I41: Share price as on xxx | K41: 315
B42: N Anand | C42: ED & CFO | D42: 8.87 | F42: 132 | I42: Number of Shares o/s | K42: 11.5 M
B43: H Malik | C43: ED | D43: 4.94 | F43: 99 | I43: Market Capitalization (in Crs) | K43: 394553
B44: B Sumant | C44: ED | D44: 11.81 | F44: 174 | I44: Less: Cash & Equivalents | K44: ='Data Sheet'!K69*-1 -> -4012.36
I45: Add: Total Debt | K45: ='Data Sheet'!K59 -> 284.54
I46: Add: Minority Interest | K46: 367.89
I47: Enterprise Value | K47: =SUM(K43:K46) -> 391193.07
...

Sheet Input Sheet
B5: Company Description | C5: ITC Limited is an Indian conglomerate, headquartered in Kolkata.[10] It has a presence across six business segments, namely FMCG, agribusiness, information technology, paper products, and packaging.[11] It generates a plurality of its revenue from tobacco products.

Sheet Share Price
A1: Date | B1: Adj Price | C1: Volume | D1: Volume
A2: 30-04-2026 | B2: 314.9 | C2: 11.54M | D2: =(VALUE(SUBSTITUTE(C2,"M",""))*1000000)/1000000 -> 11.54 | E2: 1000000
A3: 29-04-2026 | B3: 316.25 | C3: 31.2M | D3: =(VALUE(SUBSTITUTE(C3,"M",""))*1000000)/1000000 -> 31.2
A4: 28-04-2026 | B4: 304.45 | C4: 12.91M | D4: =(VALUE(SUBSTITUTE(C4,"M",""))*1000000)/1000000 -> 12.91
A5: 27-04-2026 | B5: 303.85 | C5: 14.38M | D5: =(VALUE(SUBSTITUTE(C5,"M",""))*1000000)/1000000 -> 14.38
A6: 24-04-2026 | B6: 301.6 | C6: 17.01M | D6: =(VALUE(SUBSTITUTE(C6,"M",""))*1000000)/1000000 -> 17.01
A7: 23-04-2026 | B7: 305.3 | C7: 10.70M | D7: =(VALUE(SUBSTITUTE(C7,"M",""))*1000000)/1000000 -> 10.7
A8: 22-04-2026 | B8: 305.5 | C8: 24.50M | D8: =(VALUE(SUBSTITUTE(C8,"M",""))*1000000)/1000000 -> 24.5
A9: 21-04-2026 | B9: 309.65 | C9: 24.41M | D9: =(VALUE(SUBSTITUTE(C9,"M",""))*1000000)/1000000 -> 24.41
A10: 20-04-2026 | B10: 305 | C10: 13.54M | D10: =(VALUE(SUBSTITUTE(C10,"M",""))*1000000)/1000000 -> 13.54
A11: 17-04-2026 | B11: 306.8 | C11: 35.11M | D11: =(VALUE(SUBSTITUTE(C11,"M",""))*1000000)/1000000 -> 35.11
A12: 16-04-2026 | B12: 303.4 | C12: 16.51M | D12: =(VALUE(SUBSTITUTE(C12,"M",""))*1000000)/1000000 -> 16.51
A13: 15-04-2026 | B13: 302.05 | C13: 18.70M | D13: =(VALUE(SUBSTITUTE(C13,"M",""))*1000000)/1000000 -> 18.7
A14: 13-04-2026 | B14: 298.65 | C14: 16.52M | D14: =(VALUE(SUBSTITUTE(C14,"M",""))*1000000)/1000000 -> 16.52
A15: 46299 | B15: 304.25 | C15: 17.74M | D15: =(VALUE(SUBSTITUTE(C15,"M",""))*1000000)/1000000 -> 17.74
A16: 46269 | B16: 303 | C16: 17.69M | D16: =(VALUE(SUBSTITUTE(C16,"M",""))*1000000)/1000000 -> 17.69
A17: 46238 | B17: 302.45 | C17: 22.31M | D17: =(VALUE(SUBSTITUTE(C17,"M",""))*1000000)/1000000 -> 22.31
A18: 46207 | B18: 298.45 | C18: 26.96M | D18: =(VALUE(SUBSTITUTE(C18,"M",""))*1000000)/1000000 -> 26.96
A19: 46177 | B19: 294.85 | C19: 18.05M | D19: =(VALUE(SUBSTITUTE(C19,"M",""))*1000000)/1000000 -> 18.05
A20: 46057 | B20: 292.85 | C20: 18.08M | D20: =(VALUE(SUBSTITUTE(C20,"M",""))*1000000)/1000000 -> 18.08
A21: 46026 | B21: 291.7 | C21: 18.60M | D21: =(VALUE(SUBSTITUTE(C21,"M",""))*1000000)/1000000 -> 18.6
A22: 30-03-2026 | B22: 287.7 | C22: 24.59M | D22: =(VALUE(SUBSTITUTE(C22,"M",""))*1000000)/1000000 -> 24.59
A23: 27-03-2026 | B23: 294.7 | C23: 22.18M | D23: =(VALUE(SUBSTITUTE(C23,"M",""))*1000000)/1000000 -> 22.18
A24: 25-03-2026 | B24: 295.7 | C24: 26.18M | D24: =(VALUE(SUBSTITUTE(C24,"M",""))*1000000)/1000000 -> 26.18
A25: 24-03-2026 | B25: 291.25 | C25: 33.34M | D25: =(VALUE(SUBSTITUTE(C25,"M",""))*1000000)/1000000 -> 33.34
A26: 23-03-2026 | B26: 290.45 | C26: 31.79M | D26: =(VALUE(SUBSTITUTE(C26,"M",""))*1000000)/1000000 -> 31.79
A27: 20-03-2026 | B27: 299.95 | C27: 58.68M | D27: =(VALUE(SUBSTITUTE(C27,"M",""))*1000000)/1000000 -> 58.68
A28: 19-03-2026 | B28: 298 | C28: 17.85M | D28: =(VALUE(SUBSTITUTE(C28,"M",""))*1000000)/1000000 -> 17.85
A29: 18-03-2026 | B29: 304.05 | C29: 16.70M | D29: =(VALUE(SUBSTITUTE(C29,"M",""))*1000000)/1000000 -> 16.7
A30: 17-03-2026 | B30: 304.85 | C30: 25.65M | D30: =(VALUE(SUBSTITUTE(C30,"M",""))*1000000)/1000000 -> 25.65
A31: 16-03-2026 | B31: 308.25 | C31: 37.47M | D31: =(VALUE(SUBSTITUTE(C31,"M",""))*1000000)/1000000 -> 37.47 | G31: Shareholder's name | H31: N. Shares (in Crs) | I31: % Holding | J31: Market Value (in Crs)
A32: 13-03-2026 | B32: 301.45 | C32: 25.66M | D32: =(VALUE(SUBSTITUTE(C32,"M",""))*1000000)/1000000 -> 25.66 | G32: Tobacco Manufacturers (India) Limited | H32: 222.84959 | I32: 17.79 | J32: =315*H32 -> 70197.62
A33: 46359 | B33: 304.1 | C33: 23.32M | D33: =(VALUE(SUBSTITUTE(C33,"M",""))*1000000)/1000000 -> 23.32 | G33: Life Insurance Corporation of India | H33: 198.32053 | I33: 15.83 | J33: =315*H33 -> 62470.965
A34: 46329 | B34: 309 | C34: 14.84M | D34: =(VALUE(SUBSTITUTE(C34,"M",""))*1000000)/1000000 -> 14.84 | G34: Specified Undertaking of the Unit Trust of India | H34: 97.453143 | I34: 7.78 | J34: =315*H34 -> 30697.74
A35: 46298 | B35: 309.05 | C35: 18.35M | D35: =(VALUE(SUBSTITUTE(C35,"M",""))*1000000)/1000000 -> 18.35 | G35: Myddleton Investment Company Limited | H35: 48.631194 | I35: 3.88 | J35: =315*H35 -> 15318.826
A36: 46268 | B36: 306 | C36: 14.08M | D36: =(VALUE(SUBSTITUTE(C36,"M",""))*1000000)/1000000 -> 14.08 | G36: ICICI Prudential Mutual Funds | H36: 44.801726 | I36: 3.58 | J36: =315*H36 -> 14112.544
A37: 46176 | B37: 309.7 | C37: 21.29M | D37: =(VALUE(SUBSTITUTE(C37,"M",""))*1000000)/1000000 -> 21.29 | G37: SBI Mutual Funds | H37: 41.263847 | I37: 3.29 | J37: =315*H37 -> 12998.112
A38: 46145 | B38: 311.5 | C38: 19.94M | D38: =(VALUE(SUBSTITUTE(C38,"M",""))*1000000)/1000000 -> 19.94 | G38: QIB - Insurance Company Registered | H38: 26.370496 | I38: 2.11 | J38: =315*H38 -> 8306.7064
A39: 46115 | B39: 311.95 | C39: 24.17M | D39: =(VALUE(SUBSTITUTE(C39,"M",""))*1000000)/1000000 -> 24.17 | G39: Parag Parikh Flexi Cap Mutual Funds | H39: 23.861659 | I39: 1.9 | J39: =315*H39 -> 7516.4227
A40: 46056 | B40: 314.9 | C40: 22.19M | D40: =(VALUE(SUBSTITUTE(C40,"M",""))*1000000)/1000000 -> 22.19 | G40: Goldman Sachs Trust II - Goldman Sachs GQG Partners International Opportunities Fund | H40: 21.766939 | I40: 1.74 | J40: =315*H40 -> 6856.5857
...
